<?xml version="1.0"?>  
<robot name="smartcar" xmlns:xacro="http://ros.org/wiki/xacro">  

  <xacro:macro name="smartcar_body">  
    <link name="base_link">  
    <inertial>  
      <origin xyz="0 0 0.055"/>  
      <mass value="1.0" />  
      <inertia ixx="1.0" ixy="0.0" ixz="0.0" iyy="1.0" iyz="0.0" izz="1.0"/>  
    </inertial>  
    <visual>  
      <geometry>  
        <box size="0.25 .16 .05"/>  
      </geometry>  
      <origin rpy="0 0 0" xyz="0 0 0.055"/> 
      <material name="red">  
      <color rgba="1 0 0 1"/>  
      </material>  
   </visual>  
   <collision>  
      <origin rpy="0 0 0" xyz="0 0 0.055"/>  
      <geometry>  
        <box size="0.25 .16 .05" />  
      </geometry>  
    </collision>  
  </link>  

 <link name="left_front_wheel">  
    <inertial>  
      <origin  xyz="0.08 0.08 0.025"/>  
      <mass value="0.1" />  
       <inertia ixx="1.0" ixy="0.0" ixz="0.0" iyy="1.0" iyz="0.0" izz="1.0"/>  
    </inertial>  

    <visual>  
      <geometry>  
        <cylinder length=".02" radius="0.025"/>  
      </geometry>  
      <material name="white">  
        <color rgba="1 1 1 1"/>  
      </material>  
    </visual>  
    <collision>  
      <origin rpy="0 1.57075 1.57075" xyz="0.08 0.08 0.025"/>  
      <geometry>  
         <cylinder length=".02" radius="0.025"/>  
      </geometry>  
    </collision>  
  </link>  

  <joint name="left_front_wheel_joint" type="continuous">  
    <axis xyz="0 0 1"/>  
    <parent link="base_link"/>  
    <child link="left_front_wheel"/>  
    <origin rpy="0 1.57075 1.57075" xyz="0.08 0.08 0.025"/>  
    <limit effort="100" velocity="100"/>  
    <joint_properties damping="0.0" friction="0.0"/>  
  </joint>  

  <link name="right_front_wheel">  

    <inertial>  

      <origin xyz="0.08 -0.08 0.025"/>  

      <mass value="0.1" />  

       <inertia ixx="1.0" ixy="0.0" ixz="0.0" iyy="1.0" iyz="0.0" izz="1.0"/>  

    </inertial>  

    <visual>  

      <geometry>  

        <cylinder length=".02" radius="0.025"/>  

      </geometry>  

      <material name="white">  

        <color rgba="1 1 1 1"/>  

      </material>  

    </visual>  

    <collision>  

      <origin rpy="0 1.57075 1.57075" xyz="0.08 -0.08 0.025"/>  

      <geometry>  

         <cylinder length=".02" radius="0.025"/>  

      </geometry>  

    </collision>  

  </link>  



  <joint name="right_front_wheel_joint" type="continuous">  

    <axis xyz="0 0 1"/>  

    <parent link="base_link"/>  

    <child link="right_front_wheel"/>  

    <origin rpy="0 1.57075 1.57075" xyz="0.08 -0.08 0.025"/>  

    <limit effort="100" velocity="100"/>  

    <joint_properties damping="0.0" friction="0.0"/>  

 </joint>  



 <link name="left_back_wheel">  

    <inertial>  

      <origin xyz="-0.08 0.08 0.025"/>  

      <mass value="0.1" />  

       <inertia ixx="1.0" ixy="0.0" ixz="0.0" iyy="1.0" iyz="0.0" izz="1.0"/>  

    </inertial>  

    <visual>  

      <geometry>  

        <cylinder length=".02" radius="0.025"/>  

      </geometry>  

      <material name="white">  

        <color rgba="1 1 1 1"/>  

      </material>  

   </visual>  

   <collision>  

       <origin rpy="0 1.57075 1.57075" xyz="-0.08 0.08 0.025"/>  

      <geometry>  

         <cylinder length=".02" radius="0.025"/>  

      </geometry>  

    </collision>  

  </link>  



  <joint name="left_back_wheel_joint" type="continuous">  

    <axis xyz="0 0 1"/>  

    <parent link="base_link"/>  

    <child link="left_back_wheel"/>  

    <origin rpy="0 1.57075 1.57075" xyz="-0.08 0.08 0.025"/>  

    <limit effort="100" velocity="100"/>  

    <joint_properties damping="0.0" friction="0.0"/>  

  </joint>  



  <link name="right_back_wheel">  

    <inertial>  

       <origin xyz="-0.08 -0.08 0.025"/>  

       <mass value="0.1" />  

       <inertia ixx="1.0" ixy="0.0" ixz="0.0" iyy="1.0" iyz="0.0" izz="1.0"/>  

    </inertial>  

    <visual>  

      <geometry>  

        <cylinder length=".02" radius="0.025"/>  

      </geometry>  

      <material name="white">  

        <color rgba="1 1 1 1"/>  

      </material>  

   </visual>  

   <collision>  

      <origin rpy="0 1.57075 1.57075" xyz="-0.08 -0.08 0.025"/>  

      <geometry>  

         <cylinder length=".02" radius="0.025"/>  

      </geometry>  

    </collision>  

  </link>  





  <joint name="right_back_wheel_joint" type="continuous">  

    <axis xyz="0 0 1"/>  

    <parent link="base_link"/>  

    <child link="right_back_wheel"/>  

    <origin rpy="0 1.57075 1.57075" xyz="-0.08 -0.08 0.025"/>  

    <limit effort="100" velocity="100"/>  

    <joint_properties damping="0.0" friction="0.0"/>  

  </joint>  




  <link name="camera_link">  

    <inertial>  

      <origin xyz="0.08 0 0.08"/>  

      <mass value="0.1" />  

      <inertia ixx="1.0" ixy="0.0" ixz="0.0" iyy="1.0" iyz="0.0" izz="1.0"/>  

    </inertial>  

    <visual>  

      <geometry>  

        <box size=".02 .03 .03"/>  

      </geometry>  

      <material name="white">  

        <color rgba="1 1 1 1"/>  

      </material>  

     </visual>  

     <collision>  

      <origin xyz="0.08 0 0.08"/>  

      <geometry>  

         <cylinder length=".02" radius="0.025"/>  

      </geometry>  

    </collision>  

  </link>  





  <joint name="camera_joint" type="fixed">  

    <parent link="base_link"/>  

    <child link="camera_link"/>  

    <origin xyz="0.08 0 0.08"/>  

  </joint>  





        <gazebo reference="camera_link">
            <material>Gazebo/Black</material>
        </gazebo>

        <gazebo reference="camera_link">
            <sensor type="camera" name="camera_node">
                <update_rate>30.0</update_rate>
                <camera name="head">
                    <horizontal_fov>1.3962634</horizontal_fov>
                    <image>
                        <width>1280</width>
                        <height>720</height>
                        <format>R8G8B8</format>
                    </image>
                    <clip>
                        <near>0.02</near>
                        <far>300</far>
                    </clip>
                    <noise>
                        <type>gaussian</type>
                        <mean>0.0</mean>
                        <stddev>0.007</stddev>
                    </noise>
                </camera>
                <plugin name="gazebo_camera" filename="libgazebo_ros_camera.so">
                    <alwaysOn>true</alwaysOn>
                    <updateRate>0.0</updateRate>
                    <cameraName>/camera</cameraName>
                    <imageTopicName>image_raw</imageTopicName>
                    <cameraInfoTopicName>camera_info</cameraInfoTopicName>
                    <frameName>camera_link</frameName>
                    <hackBaseline>0.07</hackBaseline>
                    <distortionK1>0.0</distortionK1>
                    <distortionK2>0.0</distortionK2>
                    <distortionK3>0.0</distortionK3>
                    <distortionT1>0.0</distortionT1>
                    <distortionT2>0.0</distortionT2>
                </plugin>
            </sensor>
        </gazebo>

<gazebo reference="base_link">
    <material>Gazebo/Blue</material>
    <turnGravityOff>false</turnGravityOff>
</gazebo>

<gazebo reference="right_front_wheel">
    <material>Gazebo/FlatBlack</material>
</gazebo>

<gazebo reference="right_back_wheel">
    <material>Gazebo/FlatBlack</material>
</gazebo>

<gazebo reference="left_front_wheel">
    <material>Gazebo/FlatBlack</material>
</gazebo>

<gazebo reference="left_back_wheel">
    <material>Gazebo/FlatBlack</material>
</gazebo>

<gazebo reference="camera_link">
    <material>Gazebo/White</material>
</gazebo>

</xacro:macro>  

</robot>
